<?xml version="1.0"?>
<robot name="panda">
  <link name="panda_link0">
    <visual>
      <geometry>
        <mesh filename="package://franka_description/meshes/visual/link0.dae" />
      </geometry>
    </visual>
    <collision>
      <geometry>
        <mesh filename="package://franka_description/meshes/collision/link0.stl" />
      </geometry>
    </collision>
  </link>
  <link name="panda_link1">
    <visual>
      <geometry>
        <mesh filename="package://franka_description/meshes/visual/link1.dae" />
      </geometry>
    </visual>
    <collision>
      <geometry>
        <mesh filename="package://franka_description/meshes/collision/link1.stl" />
      </geometry>
    </collision>
  </link>
  <joint name="panda_joint1" type="revolute">
    <origin rpy="0 0 0" xyz="0 0 0.333" />
    <parent link="panda_link0" />
    <child link="panda_link1" />
    <axis xyz="0 0 1" />
    <limit effort="0" lower="-2.8973" upper="2.8973" velocity="0" />
  </joint>
  <link name="panda_link2">
    <visual>
      <geometry>
        <mesh filename="package://franka_description/meshes/visual/link2.dae" />
      </geometry>
    </visual>
    <collision>
      <geometry>
        <mesh filename="package://franka_description/meshes/collision/link2.stl" />
      </geometry>
    </collision>
  </link>
  <joint name="panda_joint2" type="revolute">
    <origin rpy="-1.5707963267948966 0 0" xyz="0 0 0" />
    <parent link="panda_link1" />
    <child link="panda_link2" />
    <axis xyz="0 0 1" />
    <limit effort="0" lower="-1.7628" upper="1.7628" velocity="0" />
  </joint>
  <link name="panda_link3">
    <visual>
      <geometry>
        <mesh filename="package://franka_description/meshes/visual/link3.dae" />
      </geometry>
    </visual>
    <collision>
      <geometry>
        <mesh filename="package://franka_description/meshes/collision/link3.stl" />
      </geometry>
    </collision>
  </link>
  <joint name="panda_joint3" type="revolute">
    <origin rpy="1.5707963267948966 0 0" xyz="0 -0.316 0" />
    <parent link="panda_link2" />
    <child link="panda_link3" />
    <axis xyz="0 0 1" />
    <limit effort="0" lower="-2.8973" upper="2.8973" velocity="0" />
  </joint>
  <link name="panda_link4">
    <visual>
      <geometry>
        <mesh filename="package://franka_description/meshes/visual/link4.dae" />
      </geometry>
    </visual>
    <collision>
      <geometry>
        <mesh filename="package://franka_description/meshes/collision/link4.stl" />
      </geometry>
    </collision>
  </link>
  <joint name="panda_joint4" type="revolute">
    <origin rpy="1.5707963267948966 0 0" xyz="0.0825 0 0" />
    <parent link="panda_link3" />
    <child link="panda_link4" />
    <axis xyz="0 0 1" />
    <limit effort="0" lower="-3.0718" upper="-0.0698" velocity="0" />
  </joint>
  <link name="panda_link5">
    <visual>
      <geometry>
        <mesh filename="package://franka_description/meshes/visual/link5.dae" />
      </geometry>
    </visual>
    <collision>
      <geometry>
        <mesh filename="package://franka_description/meshes/collision/link5.stl" />
      </geometry>
    </collision>
  </link>
  <joint name="panda_joint5" type="revolute">
    <origin rpy="-1.5707963267948966 0 0" xyz="-0.0825 0.384 0" />
    <parent link="panda_link4" />
    <child link="panda_link5" />
    <axis xyz="0 0 1" />
    <limit effort="0" lower="-2.8973" upper="2.8973" velocity="0" />
  </joint>
  <link name="panda_link6">
    <visual>
      <geometry>
        <mesh filename="package://franka_description/meshes/visual/link6.dae" />
      </geometry>
    </visual>
    <collision>
      <geometry>
        <mesh filename="package://franka_description/meshes/collision/link6.stl" />
      </geometry>
    </collision>
  </link>
  <joint name="panda_joint6" type="revolute">
    <origin rpy="1.5707963267948966 0 0" xyz="0 0 0" />
    <parent link="panda_link5" />
    <child link="panda_link6" />
    <axis xyz="0 0 1" />
    <limit effort="0" lower="-0.0175" upper="3.7525" velocity="0" />
  </joint>
  <link name="panda_link7">
    <visual>
      <geometry>
        <mesh filename="package://franka_description/meshes/visual/link7.dae" />
      </geometry>
    </visual>
    <collision>
      <geometry>
        <mesh filename="package://franka_description/meshes/collision/link7.stl" />
      </geometry>
    </collision>
  </link>
  <joint name="panda_joint7" type="revolute">
    <origin rpy="1.5707963267948966 0 0" xyz="0.088 0 0" />
    <parent link="panda_link6" />
    <child link="panda_link7" />
    <axis xyz="0 0 1" />
    <limit effort="0" lower="-2.8973" upper="2.8973" velocity="0" />
  </joint>
  <link name="panda_link8">
  </link>
  <joint name="panda_joint8" type="fixed">
    <origin rpy="0 0 0" xyz="0 0 0.107" />
    <parent link="panda_link7" />
    <child link="panda_link8" />
  </joint>

  <link name="panda_eef">
    <visual>
      <geometry>
        <mesh filename="package://franka_description/meshes/visual/gripper.stl" />
      </geometry>
    </visual>
    <collision>
      <geometry>
        <mesh filename="package://franka_description/meshes/collision/gripper.stl" />
      </geometry>
    </collision>
  </link>
  <joint name="panda_joint_eef" type="fixed">
    <origin rpy="0 0 0" xyz="0 0 0" />
    <parent link="panda_link8" />
    <child link="panda_eef" />
  </joint>
  <link name="panda_tip" />
  <joint name="panda_joint_tip" type="fixed">
    <origin rpy="0 1.57 0" xyz="0 0 0.04" />
    <parent link="panda_eef" />
    <child link="panda_tip" />
  </joint>
</robot>